Workbook
Name Slicer_category: #N/A

Sheet raw
A1: transactions_id | B1: sale_date | C1: sale_time | D1: customer_id | E1: gender | F1: age | G1: category | H1: quantiy | I1: price_per_unit | J1: cogs | K1: total_sale
A2: 180 | B2: 44870 | C2: 0.44930556 | D2: 117 | E2: Male | F2: 41 | G2: Clothing | H2: 3 | I2: 300 | J2: 129 | K2: 900
A3: 522 | B3: 44751 | C3: 0.45833333 | D3: 52 | E3: Male | F3: 46 | G3: Beauty | H3: 3 | I3: 500 | J3: 145 | K3: 1500
A4: 559 | B4: 44907 | C4: 0.45 | D4: 5 | E4: Female | F4: 40 | G4: Clothing | H4: 4 | I4: 300 | J4: 84 | K4: 1200
A5: 1180 | B5: 44567 | C5: 0.37013889 | D5: 85 | E5: Male | F5: 41 | G5: Clothing | H5: 3 | I5: 300 | J5: 129 | K5: 900
A6: 1522 | B6: 44879 | C6: 0.35763889 | D6: 48 | E6: Male | F6: 46 | G6: Beauty | H6: 3 | I6: 500 | J6: 235 | K6: 1500
A7: 1559 | B7: 44793 | C7: 0.31944444 | D7: 49 | E7: Female | F7: 40 | G7: Clothing | H7: 4 | I7: 300 | J7: 144 | K7: 1200
A8: 163 | B8: 44865 | C8: 0.40138889 | D8: 144 | E8: Female | F8: 64 | G8: Clothing | H8: 3 | I8: 50 | J8: 23 | K8: 150
A9: 303 | B9: 44673 | C9: 0.46458333 | D9: 54 | E9: Male | F9: 19 | G9: Electronics | H9: 3 | I9: 30 | J9: 14.7 | K9: 90
A10: 421 | B10: 44659 | C10: 0.36319444 | D10: 66 | E10: Female | F10: 37 | G10: Clothing | H10: 3 | I10: 500 | J10: 235 | K10: 1500
A11: 979 | B11: 44699 | C11: 0.42916667 | D11: 6 | E11: Female | F11: 19 | G11: Beauty | H11: 1 | I11: 25 | J11: 10.5 | K11: 25
A12: 1163 | B12: 44685 | C12: 0.45277778 | D12: 120 | E12: Female | F12: 64 | G12: Clothing | H12: 3 | I12: 50 | J12: 27 | K12: 150
A13: 1303 | B13: 44639 | C13: 0.37430556 | D13: 58 | E13: Male | F13: 19 | G13: Electronics | H13: 3 | I13: 30 | J13: 15 | K13: 90
... A25: 391 | B25: 44645 | C25: 0.31736111 | D25: 68 | E25: Male | F25: 19 | G25: Beauty | H25: 2 | I25: 25 | J25: 6.25 | K25: 50
A26: 432 | B26: 44630 | C26: 0.47986111 | D26: 17 | E26: Female | G26: Electronics | H26: 2 | I26: 500 | J26: 190 | K26: 1000
A27: 1367 | B27: 44666 | C27: 0.48472222 | D27: 16 | E27: Female | G27: Electronics | H27: 1 | I27: 50 | J27: 15.5 | K27: 50
A28: 1391 | B28: 44621 | C28: 0.47847222 | D28: 130 | E28: Male | G28: Beauty | H28: 2 | I28: 25 | J28: 9.25 | K28: 50
A29: 1432 | B29: 44920 | C29: 0.26666667 | D29: 67 | E29: Female | G29: Electronics | H29: 2 | I29: 500 | J29: 245 | K29: 1000
A30: 150 | B30: 44664 | C30: 0.35069444 | D30: 89 | E30: Female | G30: Electronics | H30: 4 | I30: 30 | J30: 16.2 | K30: 120
A31: 845 | B31: 44861 | C31: 0.425 | D31: 25 | E31: Male | G31: Clothing | H31: 1 | I31: 500 | J31: 145 | K31: 500
A32: 1150 | B32: 44795 | C32: 0.41944444 | D32: 77 | E32: Female | G32: Electronics | H32: 4 | I32: 30 | J32: 10.2 | K32: 120
A33: 1845 | B33: 44705 | C33: 0.29583333 | D33: 94 | E33: Male | G33: Clothing | H33: 1 | I33: 500 | J33: 185 | K33: 500
A34: 797 | B34: 44820 | C34: 0.27638889 | D34: 116 | E34: Male | G34: Clothing | H34: 3 | I34: 25 | J34: 10.75 | K34: 75
A35: 921 | B35: 44832 | C35: 0.39861111 | D35: 101 | E35: Male | G35: Electronics | H35: 3 | I35: 25 | J35: 8 | K35: 75
A36: 1797 | B36: 44667 | C36: 0.49097222 | D36: 147 | E36: Male | F36: 40 | G36: Clothing | H36: 3 | I36: 25 | J36: 12.25 | K36: 75
A37: 1921 | B37: 44600 | C37: 0.29236111 | D37: 77 | E37: Male | F37: 51 | G37: Electronics | H37: 3 | I37: 25 | J37: 7.5 | K37: 75
A38: 291 | B38: 44887 | C38: 0.35347222 | D38: 15 | E38: Male | F38: 60 | G38: Clothing | H38: 2 | I38: 300 | J38: 126 | K38: 600
A39: 907 | B39: 44806 | C39: 0.26111111 | D39: 145 | E39: Female | F39: 45 | G39: Electronics | H39: 1 | I39: 25 | J39: 8.5 | K39: 25
A40: 1291 | B40: 44655 | C40: 0.47152778 | D40: 72 | E40: Male | F40: 60 | G40: Clothing | H40: 2 | I40: 300 | J40: 153 | K40: 600
A41: 1907 | B41: 44882 | C41: 0.47291667 | D41: 115 | E41: Female | F41: 45 | G41: Electronics | H41: 1 | I41: 25 | J41: 9 | K41: 25
A42: 860 | B42: 44662 | C42: 0.37361111 | D42: 85 | E42: Male | F42: 63 | G42: Clothing | H42: 4 | I42: 50 | J42: 16 | K42: 200
A43: 1860 | B43: 44632 | C43: 0.47291667 | D43: 57 | E43: Male | F43: 63 | G43: Clothing | H43: 4 | I43: 50 | J43: 18 | K43: 200
A44: 184 | B44: 44605 | C44: 0.28055556 | D44: 128 | E44: Male | F44: 31 | G44: Electronics | H44: 4 | I44: 50 | J44: 17 | K44: 200
A45: 734 | B45: 44632 | C45: 0.37083333 | D45: 77 | E45: Female | F45: 27 | G45: Clothing | H45: 1 | I45: 30 | J45: 15.6 | K45: 30
A46: 1184 | B46: 44604 | C46: 0.35277778 | D46: 23 | E46: Male | F46: 31 | G46: Electronics | H46: 4 | I46: 50 | J46: 27.5 | K46: 200
A47: 1734 | B47: 44620 | C47: 0.37361111 | D47: 72 | E47: Female | F47: 27 | G47: Clothing | H47: 1 | I47: 30 | J47: 14.4 | K47: 30
A48: 225 | B48: 44625 | C48: 0.31736111 | D48: 85 | E48: Female | F48: 57 | G48: Beauty | H48: 4 | I48: 25 | J48: 12.75 | K48: 100
A49: 679 | B49: 44799 | C49: 0.37430556 | D49: 64 | E49: Female | F49: 18 | G49: Beauty
A50: 746 | B50: 44747 | C50: 0.48125 | D50: 42 | E50: Female | F50: 33 | G50: Clothing
A51: 1225 | B51: 44594 | C51: 0.41041667 | D51: 137 | E51: Female | F51: 57 | G51: Beauty
...

Sheet Cleaned Data
A1: transactions_id | B1: Year_Month helper column | C1: sale_date | D1: sale_time | E1: customer_id | F1: gender | G1: age | H1: category | I1: quantiy | J1: price_per_unit | K1: cogs | L1: total_sale | M1: Sales_Data_status | N1: Sales_Calculation_check | O1: Profit
A2: 979 | B2: =TEXT(C2,"yyyy-mm") -> 2022-05 | C2: 44699 | D2: 0.42916667 | E2: 6 | F2: Female | G2: 19 | H2: Beauty | I2: 1 | J2: 25 | K2: 10.5 | L2: 25 | M2: =IF(OR(I2="",J2="",L2=""),"Incomplete","Complete") -> Complete | N2: =IF(M2="Incomplete","Not checked",IF(ROUND(I2*J2,2)=ROUND(L2,2),"Valid","Mismatch")) -> Valid | O2: =IF(M2="Incomplete","",L2-K2) -> 14.5
A3: 1979 | B3: =TEXT(C3,"yyyy-mm") -> 2022-08 | C3: 44790 | D3: 0.48194444 | E3: 102 | F3: Female | G3: 19 | H3: Beauty | I3: 1 | J3: 25 | K3: 7.75 | L3: 25 | M3: =IF(OR(I3="",J3="",L3=""),"Incomplete","Complete") -> Complete | N3: =IF(M3="Incomplete","Not checked",IF(ROUND(I3*J3,2)=ROUND(L3,2),"Valid","Mismatch")) -> Valid | O3: =IF(M3="Incomplete","",L3-K3) -> 17.25
A4: 391 | B4: =TEXT(C4,"yyyy-mm") -> 2022-03 | C4: 44645 | D4: 0.31736111 | E4: 68 | F4: Male | G4: 19 | H4: Beauty | I4: 2 | J4: 25 | K4: 6.25 | L4: 50 | M4: =IF(OR(I4="",J4="",L4=""),"Incomplete","Complete") -> Complete | N4: =IF(M4="Incomplete","Not checked",IF(ROUND(I4*J4,2)=ROUND(L4,2),"Valid","Mismatch")) -> Valid | O4: =IF(M4="Incomplete","",L4-K4) -> 43.75
A5: 1391 | B5: =TEXT(C5,"yyyy-mm") -> 2022-03 | C5: 44621 | D5: 0.47847222 | E5: 130 | F5: Male | H5: Beauty | I5: 2 | J5: 25 | K5: 9.25 | L5: 50 | M5: =IF(OR(I5="",J5="",L5=""),"Incomplete","Complete") -> Complete | N5: =IF(M5="Incomplete","Not checked",IF(ROUND(I5*J5,2)=ROUND(L5,2),"Valid","Mismatch")) -> Valid | O5: =IF(M5="Incomplete","",L5-K5) -> 40.75
A6: 797 | B6: =TEXT(C6,"yyyy-mm") -> 2022-09 | C6: 44820 | D6: 0.27638889 | E6: 116 | F6: Male | H6: Clothing | I6: 3 | J6: 25 | K6: 10.75 | L6: 75 | M6: =IF(OR(I6="",J6="",L6=""),"Incomplete","Complete") -> Complete | N6: =IF(M6="Incomplete","Not checked",IF(ROUND(I6*J6,2)=ROUND(L6,2),"Valid","Mismatch")) -> Valid | O6: =IF(M6="Incomplete","",L6-K6) -> 64.25
A7: 921 | B7: =TEXT(C7,"yyyy-mm") -> 2022-09 | C7: 44832 | D7: 0.39861111 | E7: 101 | F7: Male | H7: Electronics | I7: 3 | J7: 25 | K7: 8 | L7: 75 | M7: =IF(OR(I7="",J7="",L7=""),"Incomplete","Complete") -> Complete | N7: =IF(M7="Incomplete","Not checked",IF(ROUND(I7*J7,2)=ROUND(L7,2),"Valid","Mismatch")) -> Valid | O7: =IF(M7="Incomplete","",L7-K7) -> 67
A8: 1797 | B8: =TEXT(C8,"yyyy-mm") -> 2022-04 | C8: 44667 | D8: 0.49097222 | E8: 147 | F8: Male | G8: 40 | H8: Clothing | I8: 3 | J8: 25 | K8: 12.25 | L8: 75 | M8: =IF(OR(I8="",J8="",L8=""),"Incomplete","Complete") -> Complete | N8: =IF(M8="Incomplete","Not checked",IF(ROUND(I8*J8,2)=ROUND(L8,2),"Valid","Mismatch")) -> Valid | O8: =IF(M8="Incomplete","",L8-K8) -> 62.75
A9: 1921 | B9: =TEXT(C9,"yyyy-mm") -> 2022-02 | C9: 44600 | D9: 0.29236111 | E9: 77 | F9: Male | G9: 51 | H9: Electronics | I9: 3 | J9: 25 | K9: 7.5 | L9: 75 | M9: =IF(OR(I9="",J9="",L9=""),"Incomplete","Complete") -> Complete | N9: =IF(M9="Incomplete","Not checked",IF(ROUND(I9*J9,2)=ROUND(L9,2),"Valid","Mismatch")) -> Valid | O9: =IF(M9="Incomplete","",L9-K9) -> 67.5
A10: 907 | B10: =TEXT(C10,"yyyy-mm") -> 2022-09 | C10: 44806 | D10: 0.26111111 | E10: 145 | F10: Female | G10: 45 | H10: Electronics | I10: 1 | J10: 25 | K10: 8.5 | L10: 25 | M10: =IF(OR(I10="",J10="",L10=""),"Incomplete","Complete") -> Complete | N10: =IF(M10="Incomplete","Not checked",IF(ROUND(I10*J10,2)=ROUND(L10,2),"Valid","Mismatch")) -> Valid | O10: =IF(M10="Incomplete","",L10-K10) -> 16.5
A11: 1907 | B11: =TEXT(C11,"yyyy-mm") -> 2022-11 | C11: 44882 | D11: 0.47291667 | E11: 115 | F11: Female | G11: 45 | H11: Electronics | I11: 1 | J11: 25 | K11: 9 | L11: 25 | M11: =IF(OR(I11="",J11="",L11=""),"Incomplete","Complete") -> Complete | N11: =IF(M11="Incomplete","Not checked",IF(ROUND(I11*J11,2)=ROUND(L11,2),"Valid","Mismatch")) -> Valid | O11: =IF(M11="Incomplete","",L11-K11) -> 16
A12: 225 | B12: =TEXT(C12,"yyyy-mm") -> 2022-03 | C12: 44625 | D12: 0.31736111 | E12: 85 | F12: Female | G12: 57 | H12: Beauty | I12: 4 | J12: 25 | K12: 12.75 | L12: 100 | M12: =IF(OR(I12="",J12="",L12=""),"Incomplete","Complete") -> Complete | N12: =IF(M12="Incomplete","Not checked",IF(ROUND(I12*J12,2)=ROUND(L12,2),"Valid","Mismatch")) -> Valid | O12: =IF(M12="Incomplete","",L12-K12) -> 87.25
A13: 591 | B13: =TEXT(C13,"yyyy-mm") -> 2022-03 | C13: 44641 | D13: 0.35972222 | E13: 94 | F13: Male | G13: 53 | H13: Electronics | I13: 4 | J13: 25 | K13: 6.5 | L13: 100 | M13: =IF(OR(I13="",J13="",L13=""),"Incomplete","Complete") -> Complete | N13: =IF(M13="Incomplete","Not checked",IF(ROUND(I13*J13,2)=ROUND(L13,2),"Valid","Mismatch")) -> Valid | O13: =IF(M13="Incomplete","",L13-K13) -> 93.5
A14: 1591 | B14: =TEXT(C14,"yyyy-mm") -> 2022-09 | C14: 44833 | D14: 0.45833333 | E14: 62 | F14: Male | G14: 53 | H14: Electronics | I14: 4 | J14: 25 | K14: 7 | L14: 100 | M14: =IF(OR(I14="",J14="",L14=""),"Incomplete","Complete") -> Complete | N14: =IF(M14="Incomplete","Not checked",IF(ROUND(I14*J14,2)=ROUND(L14,2),"Valid","Mismatch")) -> Valid | O14: =IF(M14="Incomplete","",L14-K14) -> 93
A15: 713 | B15: =TEXT(C15,"yyyy-mm") -> 2022-04 | C15: 44667 | D15: 0.48819444 | E15: 39 | F15: Male | G15: 34 | H15: Beauty | I15: 3 | J15: 25 | K15: 11.25 | L15: 75 | M15: =IF(OR(I15="",J15="",L15=""),"Incomplete","Complete") -> Complete | N15: =IF(M15="Incomplete","Not checked",IF(ROUND(I15*J15,2)=ROUND(L15,2),"Valid","Mismatch")) -> Valid | O15: =IF(M15="Incomplete","",L15-K15) -> 63.75
A16: 768 | B16: =TEXT(C16,"yyyy-mm") -> 2022-06 | C16: 44739 | D16: 0.28472222 | E16: 58 | F16: Female | G16: 24 | H16: Beauty | I16: 3 | J16: 25 | K16: 10.5 | L16: 75 | M16: =IF(OR(I16="",J16="",L16=""),"Incomplete","Complete") -> Complete | N16: =IF(M16="Incomplete","Not checked",IF(ROUND(I16*J16,2)=ROUND(L16,2),"Valid","Mismatch")) -> Valid | O16: =IF(M16="Incomplete","",L16-K16) -> 64.5
A17: 1713 | B17: =TEXT(C17,"yyyy-mm") -> 2022-10 | C17: 44837 | D17: 0.42361111 | E17: 90 | F17: Male | G17: 34 | H17: Beauty | I17: 3 | J17: 25 | K17: 10.75 | L17: 75 | M17: =IF(OR(I17="",J17="",L17=""),"Incomplete","Complete") -> Complete | N17: =IF(M17="Incomplete","Not checked",IF(ROUND(I17*J17,2)=ROUND(L17,2),"Valid","Mismatch")) -> Valid | O17: =IF(M17="Incomplete","",L17-K17) -> 64.25
A18: 1768 | B18: =TEXT(C18,"yyyy-mm") -> 2022-07 | C18: 44773 | D18: 0.41111111 | E18: 85 | F18: Female | G18: 24 | H18: Beauty | I18: 3 | J18: 25 | K18: 8.75 | L18: 75 | M18: =IF(OR(I18="",J18="",L18=""),"Incomplete","Complete") -> Complete | N18: =IF(M18="Incomplete","Not checked",IF(ROUND(I18*J18,2)=ROUND(L18,2),"Valid","Mismatch")) -> Valid | O18: =IF(M18="Incomplete","",L18-K18) -> 66.25
A19: 831 | B19: =TEXT(C19,"yyyy-mm") -> 2022-11 | C19: 44895 | D19: 0.49236111 | E19: 149 | F19: Male | G19: 27 | H19: Electronics | I19: 4 | J19: 25 | K19: 13.75 | L19: 100 | M19: =IF(OR(I19="",J19="",L19=""),"Incomplete","Complete") -> Complete | N19: =IF(M19="Incomplete","Not checked",IF(ROUND(I19*J19,2)=ROUND(L19,2),"Valid","Mismatch")) -> Valid | O19: =IF(M19="Incomplete","",L19-K19) -> 86.25
... A424: 1032 | B424: =TEXT(C424,"yyyy-mm") -> 2022-04 | C424: 44652 | D424: 0.34375 | E424: 1 | F424: Male | G424: 30 | H424: Beauty | I424: 3 | J424: 30 | K424: 10.5 | L424: 90 | M424: =IF(OR(I424="",J424="",L424=""),"Incomplete","Complete") -> Complete | N424: =IF(M424="Incomplete","Not checked",IF(ROUND(I424*J424,2)=ROUND(L424,2),"Valid","Mismatch")) -> Valid | O424: =IF(M424="Incomplete","",L424-K424) -> 79.5
A425: 150 | B425: =TEXT(C425,"yyyy-mm") -> 2022-04 | C425: 44664 | D425: 0.35069444 | E425: 89 | F425: Female | H425: Electronics | I425: 4 | J425: 30 | K425: 16.2 | L425: 120 | M425: =IF(OR(I425="",J425="",L425=""),"Incomplete","Complete") -> Complete | N425: =IF(M425="Incomplete","Not checked",IF(ROUND(I425*J425,2)=ROUND(L425,2),"Valid","Mismatch")) -> Valid | O425: =IF(M425="Incomplete","",L425-K425) -> 103.8
A426: 1150 | B426: =TEXT(C426,"yyyy-mm") -> 2022-08 | C426: 44795 | D426: 0.41944444 | E426: 77 | F426: Female | H426: Electronics | I426: 4 | J426: 30 | K426: 10.2 | L426: 120 | M426: =IF(OR(I426="",J426="",L426=""),"Incomplete","Complete") -> Complete | N426: =IF(M426="Incomplete","Not checked",IF(ROUND(I426*J426,2)=ROUND(L426,2),"Valid","Mismatch")) -> Valid | O426: =IF(M426="Incomplete","",L426-K426) -> 109.8
A427: 734 | B427: =TEXT(C427,"yyyy-mm") -> 2022-03 | C427: 44632 | D427: 0.37083333 | E427: 77 | F427: Female | G427: 27 | H427: Clothing | I427: 1 | J427: 30 | K427: 15.6 | L427: 30 | M427: =IF(OR(I427="",J427="",L427=""),"Incomplete","Complete") -> Complete | N427: =IF(M427="Incomplete","Not checked",IF(ROUND(I427*J427,2)=ROUND(L427,2),"Valid","Mismatch")) -> Valid | O427: =IF(M427="Incomplete","",L427-K427) -> 14.4
A428: 1734 | B428: =TEXT(C428,"yyyy-mm") -> 2022-02 | C428: 44620 | D428: 0.37361111 | E428: 72 | F428: Female | G428: 27 | H428: Clothing | I428: 1 | J428: 30 | K428: 14.4 | L428: 30 | M428: =IF(OR(I428="",J428="",L428=""),"Incomplete","Complete") -> Complete | N428: =IF(M428="Incomplete","Not checked",IF(ROUND(I428*J428,2)=ROUND(L428,2),"Valid","Mismatch")) -> Valid | O428: =IF(M428="Incomplete","",L428-K428) -> 15.6
A429: 1679 | B429: =TEXT(C429,"yyyy-mm") -> 2022-09 | C429: 44827 | D429: 0.33888889 | E429: 71 | F429: Female | G429: 18 | H429: Beauty | I429: 3 | J429: 30 | K429: 15.3 | L429: 90 | M429: =IF(OR(I429="",J429="",L429=""),"Incomplete","Complete") -> Complete | N429: =IF(M429="Incomplete","Not checked",IF(ROUND(I429*J429,2)=ROUND(L429,2),"Valid","Mismatch")) -> Valid | O429: =IF(M429="Incomplete","",L429-K429) -> 74.7
A430: 1746 | B430: =TEXT(C430,"yyyy-mm") -> 2022-06 | C430: 44725 | D430: 0.33263889 | E430: 88 | F430: Female | G430: 33 | H430: Clothing | I430: 3 | J430: 30 | K430: 10.8 | L430: 90 | M430: =IF(OR(I430="",J430="",L430=""),"Incomplete","Complete") -> Complete | N430: =IF(M430="Incomplete","Not checked",IF(ROUND(I430*J430,2)=ROUND(L430,2),"Valid","Mismatch")) -> Valid | O430: =IF(M430="Incomplete","",L430-K430) -> 79.2
A431: 3 | B431: =TEXT(C431,"yyyy-mm") -> 2022-06 | C431: 44726 | D431: 0.29722222 | E431: 114 | F431: Male | G431: 50 | H431: Electronics | I431: 1 | J431: 30 | K431: 8.1 | L431: 30 | M431: =IF(OR(I431="",J431="",L431=""),"Incomplete","Complete") -> Complete | N431: =IF(M431="Incomplete","Not checked",IF(ROUND(I431*J431,2)=ROUND(L431,2),"Valid","Mismatch")) -> Valid | O431: =IF(M431="Incomplete","",L431-K431) -> 21.9
A432: 1003 | B432: =TEXT(C432,"yyyy-mm") -> 2022-01 | C432: 44587 | D432: 0.33263889 | E432: 80 | F432: Male | G432: 50 | H432: Electronics | I432: 1 | J432: 30 | K432: 15.9 | L432: 30 | M432: =IF(OR(I432="",J432="",L432=""),"Incomplete","Complete") -> Complete | N432: =IF(M432="Incomplete","Not checked",IF(ROUND(I432*J432,2)=ROUND(L432,2),"Valid","Mismatch")) -> Valid | O432: =IF(M432="Incomplete","",L432-K432) -> 14.1
A433: 499 | B433: =TEXT(C433,"yyyy-mm") -> 2022-04 | C433: 44654 | D433: 0.45277778 | E433: 15 | F433: Male | G433: 46 | H433: Beauty | I433: 2 | J433: 30 | K433: 16.5 | L433: 60 | M433: =IF(OR(I433="",J433="",L433=""),"Incomplete","Complete") -> Complete | N433: =IF(M433="Incomplete","Not checked",IF(ROUND(I433*J433,2)=ROUND(L433,2),"Valid","Mismatch")) -> Valid | O433: =IF(M433="Incomplete","",L433-K433) -> 43.5
A434: 1499 | B434: =TEXT(C434,"yyyy-mm") -> 2022-09 | C434: 44827 | D434: 0.40694444 | E434: 3 | F434: Male | G434: 46 | H434: Beauty | I434: 2 | J434: 30 | K434: 11.7 | L434: 60 | M434: =IF(OR(I434="",J434="",L434=""),"Incomplete","Complete") -> Complete | N434: =IF(M434="Incomplete","Not checked",IF(ROUND(I434*J434,2)=ROUND(L434,2),"Valid","Mismatch")) -> Valid | O434: =IF(M434="Incomplete","",L434-K434) -> 48.3
A435: 14 | B435: =TEXT(C435,"yyyy-mm") -> 2022-05 | C435: 44699 | D435: 0.29930556 | E435: 8 | F435: Male | G435: 64 | H435: Clothing | I435: 4 | J435: 30 | K435: 13.2 | L435: 120 | M435: =IF(OR(I435="",J435="",L435=""),"Incomplete","Complete") -> Complete | N435: =IF(M435="Incomplete","Not checked",IF(ROUND(I435*J435,2)=ROUND(L435,2),"Valid","Mismatch")) -> Valid | O435: =IF(M435="Incomplete","",L435-K435) -> 106.8
A436: 1014 | B436: =TEXT(C436,"yyyy-mm") -> 2022-02 | C436: 44596 | D436: 0.43472222 | E436: 147 | F436: Male | G436: 64 | H436: Clothing | I436: 4 | J436: 30 | K436: 11.4 | L436: 120 | M436: =IF(OR(I436="",J436="",L436=""),"Incomplete","Complete") -> Complete | N436: =IF(M436="Incomplete","Not checked",IF(ROUND(I436*J436,2)=ROUND(L436,2),"Valid","Mismatch")) -> Valid | O436: =IF(M436="Incomplete","",L436-K436) -> 108.6
A437: 438 | B437: =TEXT(C437,"yyyy-mm") -> 2022-08 | C437: 44804 | D437: 0.42708333 | E437: 88 | F437: Female | G437: 42 | H437: Clothing | I437: 1 | J437: 30 | K437: 15.9 | L437: 30 | M437: =IF(OR(I437="",J437="",L437=""),"Incomplete","Complete") -> Complete | N437: =IF(M437="Incomplete","Not checked",IF(ROUND(I437*J437,2)=ROUND(L437,2),"Valid","Mismatch")) -> Valid | O437: =IF(M437="Incomplete","",L437-K437) -> 14.1
A438: 1438 | B438: =TEXT(C438,"yyyy-mm") -> 2022-01 | C438: 44568 | D438: 0.41666667 | E438: 72 | F438: Female | G438: 42 | H438: Clothing | I438: 1 | J438: 30 | K438: 13.8 | L438: 30 | M438: =IF(OR(I438="",J438="",L438=""),"Incomplete","Complete") -> Complete | N438: =IF(M438="Incomplete","Not checked",IF(ROUND(I438*J438,2)=ROUND(L438,2),"Valid","Mismatch")) -> Valid | O438: =IF(M438="Incomplete","",L438-K438) -> 16.2
... A789: 367 | B789: =TEXT(C789,"yyyy-mm") -> 2022-12 | C789: 44925 | D789: 0.29375 | E789: 123 | F789: Female | G789: 57 | H789: Electronics | I789: 1 | J789: 50 | K789: 18 | L789: 50 | M789: =IF(OR(I789="",J789="",L789=""),"Incomplete","Complete") -> Complete | N789: =IF(M789="Incomplete","Not checked",IF(ROUND(I789*J789,2)=ROUND(L789,2),"Valid","Mismatch")) -> Valid | O789: =IF(M789="Incomplete","",L789-K789) -> 32
A790: 1367 | B790: =TEXT(C790,"yyyy-mm") -> 2022-04 | C790: 44666 | D790: 0.48472222 | E790: 16 | F790: Female | H790: Electronics | I790: 1 | J790: 50 | K790: 15.5 | L790: 50 | M790: =IF(OR(I790="",J790="",L790=""),"Incomplete","Complete") -> Complete | N790: =IF(M790="Incomplete","Not checked",IF(ROUND(I790*J790,2)=ROUND(L790,2),"Valid","Mismatch")) -> Valid | O790: =IF(M790="Incomplete","",L790-K790) -> 34.5
A791: 860 | B791: =TEXT(C791,"yyyy-mm") -> 2022-04 | C791: 44662 | D791: 0.37361111 | E791: 85 | F791: Male | G791: 63 | H791: Clothing | I791: 4 | J791: 50 | K791: 16 | L791: 200 | M791: =IF(OR(I791="",J791="",L791=""),"Incomplete","Complete") -> Complete | N791: =IF(M791="Incomplete","Not checked",IF(ROUND(I791*J791,2)=ROUND(L791,2),"Valid","Mismatch")) -> Valid | O791: =IF(M791="Incomplete","",L791-K791) -> 184
A792: 1860 | B792: =TEXT(C792,"yyyy-mm") -> 2022-03 | C792: 44632 | D792: 0.47291667 | E792: 57 | F792: Male | G792: 63 | H792: Clothing | I792: 4 | J792: 50 | K792: 18 | L792: 200 | M792: =IF(OR(I792="",J792="",L792=""),"Incomplete","Complete") -> Complete | N792: =IF(M792="Incomplete","Not checked",IF(ROUND(I792*J792,2)=ROUND(L792,2),"Valid","Mismatch")) -> Valid | O792: =IF(M792="Incomplete","",L792-K792) -> 182
A793: 184 | B793: =TEXT(C793,"yyyy-mm") -> 2022-02 | C793: 44605 | D793: 0.28055556 | E793: 128 | F793: Male | G793: 31 | H793: Electronics | I793: 4 | J793: 50 | K793: 17 | L793: 200 | M793: =IF(OR(I793="",J793="",L793=""),"Incomplete","Complete") -> Complete | N793: =IF(M793="Incomplete","Not checked",IF(ROUND(I793*J793,2)=ROUND(L793,2),"Valid","Mismatch")) -> Valid | O793: =IF(M793="Incomplete","",L793-K793) -> 183
A794: 1184 | B794: =TEXT(C794,"yyyy-mm") -> 2022-02 | C794: 44604 | D794: 0.35277778 | E794: 23 | F794: Male | G794: 31 | H794: Electronics | I794: 4 | J794: 50 | K794: 27.5 | L794: 200 | M794: =IF(OR(I794="",J794="",L794=""),"Incomplete","Complete") -> Complete | N794: =IF(M794="Incomplete","Not checked",IF(ROUND(I794*J794,2)=ROUND(L794,2),"Valid","Mismatch")) -> Valid | O794: =IF(M794="Incomplete","",L794-K794) -> 172.5
...

Sheet Data Quality
A1: CHECK | B1: RESULT | C1: ACTION | D1: Final Quality Summary
A2: Blank transaction IDs | B2: 0 | C2: No action required | D2: Total records 2000
A3: Duplicate transaction IDs | B3: 0 | C3: No action required | D3: Complete sales record 1997
A4: Blank sale dates | B4: 0 | C4: No action required | D4: incomplete sales records 3
A5: Ealiest sale date | B5: =MIN('Cleaned Data'!C:C) -> 44562 | C5: No action required | D5: missing ages 10
A6: Latest sale date | B6: =MAX('Cleaned Data'!C:C) -> 45291 | C6: No action required | D6: duplicate transaction ids 0
A7: Dates recognized by Excel | B7: =COUNT('Cleaned Data'!C:C) -> 2000 | D7: date range january 1, 2022 - december 31, 2023
A8: Total transaction records | B8: =COUNTA('Cleaned Data'!A:A)-1 -> 2000 | D8: sales calculation mismatches 0
A9: Sale times recognized by Excel | B9: =COUNT('Cleaned Data'!D:D) -> 2000
A10: Blank customer IDs | B10: 0
A11: Gender Blank | B11: 0
A12: Blank ages | B12: 10 | C12: Retain records; exclude blanks from age analysis
A13: Minimum age | B13: =MIN('Cleaned Data'!G:G) -> 18
A14: Maximum age | B14: =MAX('Cleaned Data'!G:G) -> 64
A15: Ages recognized as numbers | B15: =COUNT('Cleaned Data'!G:G) -> 1990
A16: Blank categories | B16: 0
A17: Missing sales fields | B17: 3 | C17: Flagged as incomplete exclude from sales calculations
A18: Minimum quantity | B18: =MIN('Cleaned Data'!I:I) -> 1
A19: Maximum quantity | B19: =MAX('Cleaned Data'!I:I) -> 4
A20: Quantity range | B20: 1 to 4 | C20: No correction required
A21: Minimum Price Per Unit | B21: =MIN('Cleaned Data'!J:J) -> 25
A22: Maximum Price Per Unit | B22: =MAX('Cleaned Data'!J:J) -> 500
A23: Pricer per unit range | B23: 25 to 500 | C23: no correction required
A24: COGS range | B24: 6.25 to 620 | C24: Further validation required

Sheet PivotTables
A1: Sales_Data_status | B1: Complete
A3: category | B3: Sum of total_sale | C3: Sum of Profit
A4: Beauty | B4: 286840 | C4: 228630.15
A5: Clothing | B5: 311070 | C5: 246679.5
A6: Electronics | B6: 313810 | C6: 246647.65
A7: Grand Total | B7: 911720 | C7: 721957.3

Sheet Dashboard
A1: Retail Sales Dashboard
J2: Key Business Insights
A3: Total revenue | C3: Total profit | E3: Complete Transaction | G3: Profit Margin | J3: Electronics generated the highest revenue of $313,810, while Beauty generated the lowest revenue of $286,840.
A4: =SUMIFS('Cleaned Data'!L:L,'Cleaned Data'!M:M,"Complete") -> 911720 | C4: =SUMIFS('Cleaned Data'!O:O,'Cleaned Data'!M:M,"Complete") -> 721957.3 | E4: =COUNTIF('Cleaned Data'!M:M,"Complete") -> 1997 | G4: =C4/A4 -> 0.79186296
J5: The business generated total revenue of $911,720 and total profit of $721,957.30, giving a profit margin of 79.19%.
J7: The analysis contains 1,997 complete transactions after the data-cleaning process.

Sheet Lookup Tool
A1: Transaction Lookup
A2: Transaction ID | B2: 99999
A4: Sale Date | B4: =_xlfn.XLOOKUP($B$2,'Cleaned Data'!A:A,'Cleaned Data'!B:B,"Not found") -> Not found
A5: Sale Time | B5: =_xlfn.XLOOKUP($B$2,'Cleaned Data'!A:A,'Cleaned Data'!C:C,"Not found") -> Not found
A7: Customer ID | B7: =_xlfn.XLOOKUP($B$2,'Cleaned Data'!A:A,'Cleaned Data'!E:E,"Not found") -> Not found
A8: Category | B8: =_xlfn.XLOOKUP($B$2,'Cleaned Data'!A:A,'Cleaned Data'!H:H,"Not found") -> Not found
A9: Total Sale | B9: =_xlfn.XLOOKUP($B$2,'Cleaned Data'!A:A,'Cleaned Data'!L:L,"Not found") -> Not found
A10: Profit | B10: =_xlfn.XLOOKUP($B$2,'Cleaned Data'!A:A,'Cleaned Data'!O:O,"Not found") -> Not found

Sheet Analysis SummaryRetail
A1: Retail Sales Analysis Summary
A3: Analysis Area | C3: Key Finding
A4: Revenue by Category | C4: Electronics generated the highest revenue of 313,810, while Beauty generated the lowest revenue of 286,840. Total revenue across all categories was 911,720.
A6: Profit by Category | C6: Clothing generated the highest profit at 246,679.50, slightly exceeding Electronics by 31.85. Electronics generated the highest revenue at 313,810, while Beauty had the lowest revenue and profit. Total profit was 721,957.30.
A8: Monthly Revenue Trend | C8: February 2022 generated the lowest monthly revenue at 16,110, while December 2022 generated the highest at 72,880

Sheet Monthly Analysis
A1: Sales_Data_status | B1: Complete
A3: Year_Month helper column | B3: Sum of total_sale
A4: 2022-02 | B4: 16110
A5: 2023-03 | B5: 20530
A6: 2022-06 | B6: 20700
A7: 2022-08 | B7: 21195
A8: 2023-04 | B8: 21925
A9: 2022-07 | B9: 22195
A10: 2022-01 | B10: 22635
A11: 2023-01 | B11: 23790
A12: 2022-03 | B12: 24505
A13: 2023-06 | B13: 24555
A14: 2022-05 | B14: 24980
A15: 2023-02 | B15: 25170
... A28: Grand Total | B28: 911720
